Workbook

Sheet Aero y mesh
E2: x= 15 m
B4: alfa | C4: Coeff Sustentación | D4: Coeff Resistencia | E4: Coeff Momentos | F4: Rend aerodinámico | H4: Número de nodos | I4: Número de elementos | J4: Calidad Aspect Ratio Max | K4: Calidad min orthogonal ratio
B6: -5 | C6: -0.07 | D6: 0.0292 | E6: -0.0397 | F6: =C6/D6 -> -2.3972603 | H6: 87341 | I6: 473300 | J6: 125.31 | K6: 0.0102951
B7: -4 | C7: 0.0359 | D7: 0.0269 | E7: -0.0423 | F7: =C7/D7 -> 1.3345725 | H7: 86791 | I7: 470696 | J7: 198.553 | K7: 0.00883256
B8: -3 | C8: 0.1456 | D8: 0.0265 | E8: -0.0488 | F8: =C8/D8 -> 5.4943396 | H8: 87155 | I8: 472181 | J8: 112.66 | K8: 0.020276
B9: -2 | C9: 0.252 | D9: 0.0274 | E9: -0.0608 | F9: =C9/D9 -> 9.1970803 | H9: 86893 | I9: 470635 | J9: 87.2705 | K9: 0.0217952
B10: -1 | C10: 0.362 | D10: 0.03 | E10: -0.079 | F10: =C10/D10 -> 12.066667 | H10: 87118 | I10: 472130 | J10: 64.8864 | K10: 0.0444164
B11: 0 | C11: 0.468 | D11: 0.0333 | E11: -0.0955 | F11: =C11/D11 -> 14.054054 | H11: 87306 | I11: 473221 | J11: 146.72 | K11: 0.0134789
B12: 1 | C12: 0.5748 | D12: 0.0379 | E12: -0.119 | F12: =C12/D12 -> 15.166227 | H12: 86933 | I12: 470874 | J12: 75.0645 | K12: 0.04
B13: 2 | C13: 0.675 | D13: 0.0442 | E13: -0.146 | F13: =C13/D13 -> 15.271493 | H13: 87139 | I13: 472213 | J13: 89.116 | K13: 0.00999
B14: 3 | C14: 0.777 | D14: 0.0516 | E14: -0.177 | F14: =C14/D14 -> 15.05814 | H14: 86991 | I14: 471446 | J14: 87.98 | K14: 0.0279956
B15: 4 | C15: 0.87279 | D15: 0.06135 | E15: -0.21433 | F15: =C15/D15 -> 14.226406 | H15: 87123 | I15: 471995 | J15: 107.955 | K15: 0.0094216
B16: 5 | C16: 0.96441 | D16: 0.07253 | E16: -0.2559 | F16: =C16/D16 -> 13.296705 | H16: 87166 | I16: 472296 | J16: 92.3836 | K16: 0.025587
B17: 6 | C17: 1.0457 | D17: 0.08412 | E17: -0.298 | F17: =C17/D17 -> 12.431051 | H17: 86791 | I17: 470364 | J17: 88.6853 | K17: 0.0215322
... B26: 15 | C26: 1.1513 | D26: 0.26685 | E26: -0.7789 | F26: =C26/D26 -> 4.3144088 | H26: 86743 | I26: 470078 | J26: 115.76 | K26: 0.00703892

Sheet Efecto suelo
B3: alfa = 0º | J3: alfa 0º sin efecto suelo
B4: tamaño divisiones | C4: h | D4: h/(b/2) | E4: Coeff Sust | F4: Coeff Resist | G4: Coeff mom | H4: Rendimiento aerodi | K4: Cl | L4: Cd | M4: Cm | N4: rend
A5: b/2 | B5: 0.1 | C5: =2.5 -> 2.5 | D5: =C5/$A$6 -> 0.16666667 | E5: 0.46753654 | F5: 0.030147959 | G5: -0.13383678 | H5: =E5/F5 -> 15.508066 | K5: ='Aero y mesh'!$C$11 -> 0.468 | L5: ='Aero y mesh'!$D$11 -> 0.0333 | M5: ='Aero y mesh'!$E$11 -> -0.0955 | N5: ='Aero y mesh'!$F$11 -> 14.054054
A6: 15 | C6: =C5+$B$5 -> 2.6 | D6: =C6/$A$6 -> 0.17333333 | E6: 0.47110191 | F6: 0.030384137 | G6: -0.13145998 | H6: =E6/F6 -> 15.504864 | K6: ='Aero y mesh'!$C$11 -> 0.468 | L6: ='Aero y mesh'!$D$11 -> 0.0333 | M6: ='Aero y mesh'!$E$11 -> -0.0955 | N6: ='Aero y mesh'!$F$11 -> 14.054054
C7: =C6+$B$5 -> 2.7 | D7: =C7/$A$6 -> 0.18 | E7: 0.47431565 | F7: 0.030459636 | G7: -0.13022242 | H7: =E7/F7 -> 15.571941 | K7: ='Aero y mesh'!$C$11 -> 0.468 | L7: ='Aero y mesh'!$D$11 -> 0.0333 | M7: ='Aero y mesh'!$E$11 -> -0.0955 | N7: ='Aero y mesh'!$F$11 -> 14.054054
C8: =C7+$B$5 -> 2.8 | D8: =C8/$A$6 -> 0.18666667 | E8: 0.47752938 | F8: 0.030535135 | G8: -0.12898486 | H8: =E8/F8 -> 15.638686 | K8: ='Aero y mesh'!$C$11 -> 0.468 | L8: ='Aero y mesh'!$D$11 -> 0.0333 | M8: ='Aero y mesh'!$E$11 -> -0.0955 | N8: ='Aero y mesh'!$F$11 -> 14.054054
C9: =C8+$B$5 -> 2.9 | D9: =C9/$A$6 -> 0.19333333 | E9: 0.48074312 | F9: 0.030610634 | G9: -0.1277473 | H9: =E9/F9 -> 15.705102 | K9: ='Aero y mesh'!$C$11 -> 0.468 | L9: ='Aero y mesh'!$D$11 -> 0.0333 | M9: ='Aero y mesh'!$E$11 -> -0.0955 | N9: ='Aero y mesh'!$F$11 -> 14.054054
C10: =C9+$B$5 -> 3 | D10: =C10/$A$6 -> 0.2 | E10: 0.48395685 | F10: 0.030686133 | G10: -0.12650974 | H10: =E10/F10 -> 15.77119 | K10: ='Aero y mesh'!$C$11 -> 0.468 | L10: ='Aero y mesh'!$D$11 -> 0.0333 | M10: ='Aero y mesh'!$E$11 -> -0.0955 | N10: ='Aero y mesh'!$F$11 -> 14.054054
C11: =C10+$B$5 -> 3.1 | D11: =C11/$A$6 -> 0.20666667 | E11: 0.48717058 | F11: 0.030761632 | G11: -0.12527218 | H11: =E11/F11 -> 15.836955 | K11: ='Aero y mesh'!$C$11 -> 0.468 | L11: ='Aero y mesh'!$D$11 -> 0.0333 | M11: ='Aero y mesh'!$E$11 -> -0.0955 | N11: ='Aero y mesh'!$F$11 -> 14.054054
C12: =C11+$B$5 -> 3.2 | D12: =C12/$A$6 -> 0.21333333 | E12: 0.49038432 | F12: 0.030837131 | G12: -0.12403462 | H12: =E12/F12 -> 15.902398 | K12: ='Aero y mesh'!$C$11 -> 0.468 | L12: ='Aero y mesh'!$D$11 -> 0.0333 | M12: ='Aero y mesh'!$E$11 -> -0.0955 | N12: ='Aero y mesh'!$F$11 -> 14.054054
C13: =C12+$B$5 -> 3.3 | D13: =C13/$A$6 -> 0.22 | E13: 0.49359805 | F13: 0.03091263 | G13: -0.12279706 | H13: =E13/F13 -> 15.96752 | K13: ='Aero y mesh'!$C$11 -> 0.468 | L13: ='Aero y mesh'!$D$11 -> 0.0333 | M13: ='Aero y mesh'!$E$11 -> -0.0955 | N13: ='Aero y mesh'!$F$11 -> 14.054054
C14: =C13+$B$5 -> 3.4 | D14: =C14/$A$6 -> 0.22666667 | E14: 0.49478458 | F14: 0.030966604 | G14: -0.12177178 | H14: =E14/F14 -> 15.978006 | K14: ='Aero y mesh'!$C$11 -> 0.468 | L14: ='Aero y mesh'!$D$11 -> 0.0333 | M14: ='Aero y mesh'!$E$11 -> -0.0955 | N14: ='Aero y mesh'!$F$11 -> 14.054054
C15: =C14+$B$5 -> 3.5 | D15: =C15/$A$6 -> 0.23333333 | E15: 0.4943944 | F15: 0.031003836 | G15: -0.12091159 | H15: =E15/F15 -> 15.946233 | K15: ='Aero y mesh'!$C$11 -> 0.468 | L15: ='Aero y mesh'!$D$11 -> 0.0333 | M15: ='Aero y mesh'!$E$11 -> -0.0955 | N15: ='Aero y mesh'!$F$11 -> 14.054054
C16: =C15+$B$5 -> 3.6 | D16: =C16/$A$6 -> 0.24 | E16: 0.49400422 | F16: 0.031041068 | G16: -0.12005141 | H16: =E16/F16 -> 15.914537 | K16: ='Aero y mesh'!$C$11 -> 0.468 | L16: ='Aero y mesh'!$D$11 -> 0.0333 | M16: ='Aero y mesh'!$E$11 -> -0.0955 | N16: ='Aero y mesh'!$F$11 -> 14.054054
C17: =C16+$B$5 -> 3.7 | D17: =C17/$A$6 -> 0.24666667 | E17: 0.49361404 | F17: 0.0310783 | G17: -0.11919123 | H17: =E17/F17 -> 15.882917 | K17: ='Aero y mesh'!$C$11 -> 0.468 | L17: ='Aero y mesh'!$D$11 -> 0.0333 | M17: ='Aero y mesh'!$E$11 -> -0.0955 | N17: ='Aero y mesh'!$F$11 -> 14.054054
C18: =C17+$B$5 -> 3.8 | D18: =C18/$A$6 -> 0.25333333 | E18: 0.49322386 | F18: 0.031115531 | G18: -0.11833104 | H18: =E18/F18 -> 15.851372 | K18: ='Aero y mesh'!$C$11 -> 0.468 | L18: ='Aero y mesh'!$D$11 -> 0.0333 | M18: ='Aero y mesh'!$E$11 -> -0.0955 | N18: ='Aero y mesh'!$F$11 -> 14.054054
... C130: =C129+$B$5 -> 15 | D130: =C130/$A$6 -> 1 | E130: 0.47988716 | F130: 0.032945532 | G130: -0.098765583 | H130: =E130/F130 -> 14.566077 | K130: ='Aero y mesh'!$C$11 -> 0.468 | L130: ='Aero y mesh'!$D$11 -> 0.0333 | M130: ='Aero y mesh'!$E$11 -> -0.0955 | N130: ='Aero y mesh'!$F$11 -> 14.054054

Sheet v2
B3: alfa = 0º | J3: alfa 0º sin efecto suelo
B4: tamaño divisiones | C4: h | D4: h/(b/2) | E4: Coeff Sust | F4: Coeff Resist | G4: Coeff mom | H4: Rendimiento aerodi | K4: Cl | L4: Cd | M4: Cm | N4: rend
A5: b/2 | B5: 0.1 | C5: =2.5 -> 2.5 | D5: =C5/$A$6 -> 0.16666667 | E5: 0.46852747 | F5: 0.030108098 | G5: -0.13352935 | H5: =E5/F5 -> 15.56151 | K5: ='Aero y mesh'!$C$11 -> 0.468 | L5: ='Aero y mesh'!$D$11 -> 0.0333 | M5: ='Aero y mesh'!$E$11 -> -0.0955 | N5: ='Aero y mesh'!$F$11 -> 14.054054
A6: 15 | C6: =C5+$B$5 -> 2.6 | D6: =C6/$A$6 -> 0.17333333 | E6: 0.47190317 | F6: 0.030189247 | G6: -0.13197908 | H6: =E6/F6 -> 15.631498 | K6: ='Aero y mesh'!$C$11 -> 0.468 | L6: ='Aero y mesh'!$D$11 -> 0.0333 | M6: ='Aero y mesh'!$E$11 -> -0.0955 | N6: ='Aero y mesh'!$F$11 -> 14.054054
C7: =C6+$B$5 -> 2.7 | D7: =C7/$A$6 -> 0.18 | E7: 0.47527887 | F7: 0.030270397 | G7: -0.13042881 | H7: =E7/F7 -> 15.701111 | K7: ='Aero y mesh'!$C$11 -> 0.468 | L7: ='Aero y mesh'!$D$11 -> 0.0333 | M7: ='Aero y mesh'!$E$11 -> -0.0955 | N7: ='Aero y mesh'!$F$11 -> 14.054054
C8: =C7+$B$5 -> 2.8 | D8: =C8/$A$6 -> 0.18666667 | E8: 0.47865456 | F8: 0.030351546 | G8: -0.12887854 | H8: =E8/F8 -> 15.770352 | K8: ='Aero y mesh'!$C$11 -> 0.468 | L8: ='Aero y mesh'!$D$11 -> 0.0333 | M8: ='Aero y mesh'!$E$11 -> -0.0955 | N8: ='Aero y mesh'!$F$11 -> 14.054054
C9: =C8+$B$5 -> 2.9 | D9: =C9/$A$6 -> 0.19333333 | E9: 0.48203026 | F9: 0.030432695 | G9: -0.12732827 | H9: =E9/F9 -> 15.839223 | K9: ='Aero y mesh'!$C$11 -> 0.468 | L9: ='Aero y mesh'!$D$11 -> 0.0333 | M9: ='Aero y mesh'!$E$11 -> -0.0955 | N9: ='Aero y mesh'!$F$11 -> 14.054054
C10: =C9+$B$5 -> 3 | D10: =C10/$A$6 -> 0.2 | E10: 0.48540596 | F10: 0.030513845 | G10: -0.125778 | H10: =E10/F10 -> 15.907729 | K10: ='Aero y mesh'!$C$11 -> 0.468 | L10: ='Aero y mesh'!$D$11 -> 0.0333 | M10: ='Aero y mesh'!$E$11 -> -0.0955 | N10: ='Aero y mesh'!$F$11 -> 14.054054
C11: =C10+$B$5 -> 3.1 | D11: =C11/$A$6 -> 0.20666667 | E11: 0.48878166 | F11: 0.030594994 | G11: -0.12422773 | H11: =E11/F11 -> 15.97587 | K11: ='Aero y mesh'!$C$11 -> 0.468 | L11: ='Aero y mesh'!$D$11 -> 0.0333 | M11: ='Aero y mesh'!$E$11 -> -0.0955 | N11: ='Aero y mesh'!$F$11 -> 14.054054
C12: =C11+$B$5 -> 3.2 | D12: =C12/$A$6 -> 0.21333333 | E12: 0.49215736 | F12: 0.030676143 | G12: -0.12267745 | H12: =E12/F12 -> 16.043652 | K12: ='Aero y mesh'!$C$11 -> 0.468 | L12: ='Aero y mesh'!$D$11 -> 0.0333 | M12: ='Aero y mesh'!$E$11 -> -0.0955 | N12: ='Aero y mesh'!$F$11 -> 14.054054
C13: =C12+$B$5 -> 3.3 | D13: =C13/$A$6 -> 0.22 | E13: 0.4950549 | F13: 0.030753991 | G13: -0.12122842 | H13: =E13/F13 -> 16.097257 | K13: ='Aero y mesh'!$C$11 -> 0.468 | L13: ='Aero y mesh'!$D$11 -> 0.0333 | M13: ='Aero y mesh'!$E$11 -> -0.0955 | N13: ='Aero y mesh'!$F$11 -> 14.054054
C14: =C13+$B$5 -> 3.4 | D14: =C14/$A$6 -> 0.22666667 | E14: 0.49588044 | F14: 0.03081753 | G14: -0.12021806 | H14: =E14/F14 -> 16.090856 | K14: ='Aero y mesh'!$C$11 -> 0.468 | L14: ='Aero y mesh'!$D$11 -> 0.0333 | M14: ='Aero y mesh'!$E$11 -> -0.0955 | N14: ='Aero y mesh'!$F$11 -> 14.054054
C15: =C14+$B$5 -> 3.5 | D15: =C15/$A$6 -> 0.23333333 | E15: 0.49670598 | F15: 0.030881069 | G15: -0.11920771 | H15: =E15/F15 -> 16.084481 | K15: ='Aero y mesh'!$C$11 -> 0.468 | L15: ='Aero y mesh'!$D$11 -> 0.0333 | M15: ='Aero y mesh'!$E$11 -> -0.0955 | N15: ='Aero y mesh'!$F$11 -> 14.054054
C16: =C15+$B$5 -> 3.6 | D16: =C16/$A$6 -> 0.24 | E16: 0.49753151 | F16: 0.030944609 | G16: -0.11819735 | H16: =E16/F16 -> 16.078132 | K16: ='Aero y mesh'!$C$11 -> 0.468 | L16: ='Aero y mesh'!$D$11 -> 0.0333 | M16: ='Aero y mesh'!$E$11 -> -0.0955 | N16: ='Aero y mesh'!$F$11 -> 14.054054
C17: =C16+$B$5 -> 3.7 | D17: =C17/$A$6 -> 0.24666667 | E17: 0.49835705 | F17: 0.031008148 | G17: -0.117187 | H17: =E17/F17 -> 16.07181 | K17: ='Aero y mesh'!$C$11 -> 0.468 | L17: ='Aero y mesh'!$D$11 -> 0.0333 | M17: ='Aero y mesh'!$E$11 -> -0.0955 | N17: ='Aero y mesh'!$F$11 -> 14.054054
C18: =C17+$B$5 -> 3.8 | D18: =C18/$A$6 -> 0.25333333 | E18: 0.49918259 | F18: 0.031071687 | G18: -0.11617664 | H18: =E18/F18 -> 16.065513 | K18: ='Aero y mesh'!$C$11 -> 0.468 | L18: ='Aero y mesh'!$D$11 -> 0.0333 | M18: ='Aero y mesh'!$E$11 -> -0.0955 | N18: ='Aero y mesh'!$F$11 -> 14.054054
... C130: =C129+$B$5 -> 15 | D130: =C130/$A$6 -> 1 | E130: 0.47447681 | F130: 0.032532867 | G130: -0.099612832 | H130: =E130/F130 -> 14.584537 | K130: ='Aero y mesh'!$C$11 -> 0.468 | L130: ='Aero y mesh'!$D$11 -> 0.0333 | M130: ='Aero y mesh'!$E$11 -> -0.0955 | N130: ='Aero y mesh'!$F$11 -> 14.054054

Sheet Cp(y=3m)
A2: Entre el encastre y el motor
C3: X | D3: Y | G3: X | H3: Y | K3: X | L3: Y | O3: X | P3: Y | S3: X | T3: Y | W3: X | X3: Y | AA3: X | AB3: Y | AE3: X | AF3: Y | AI3: X | AJ3: Y | AM3: X | AN3: Y | AQ3: X | AR3: Y | AU3: X | AV3: Y | AY3: X | AZ3: Y | BC3: X | BD3: Y | BG3: X | BH3: Y | BK3: X | BL3: Y | BO3: X | BP3: Y | BS3: X | BT3: Y | BW3: X | BX3: Y | CA3: X | CB3: Y | CE3: X | CF3: Y
B5: alfa | F5: alfa | J5: alfa | N5: alfa | R5: alfa | V5: alfa | Z5: alfa | AD5: alfa | AH5: alfa | AL5: alfa | AP5: alfa | AT5: alfa | AX5: alfa | BB5: alfa | BF5: alfa | BJ5: alfa | BN5: alfa | BR5: alfa | BV5: alfa | BZ5: alfa | CD5: alfa
B6: -5 | F6: -4 | J6: -3 | N6: -2 | R6: -1 | V6: 0 | Z6: 1 | AD6: 2 | AH6: 3 | AL6: 4 | AP6: 5 | AT6: 6 | AX6: 7 | BB6: 8 | BF6: 9 | BJ6: 10 | BN6: 11 | BR6: 12 | BV6: 13 | BZ6: 14 | CD6: 15
C7: -1.25569 | D7: -0.548488 | G7: -0.284532 | H7: -0.361455 | K7: -0.874594 | L7: -0.407287 | O7: 0.235894 | P7: -0.360068 | S7: -2.07403 | T7: -0.274109 | W7: -11.8791 | X7: 0.548417 | AA7: 0.496072 | AB7: 0.00577764 | AE7: 1.90999 | AF7: 0.177061 | AI7: -0.193693 | AJ7: -0.500272 | AM7: 0.455333 | AN7: -0.42444 | AQ7: -2.57986 | AR7: -0.678292 | AU7: -1.14563 | AV7: -0.0195753 | AY7: 0.593136 | AZ7: -0.401708 | BC7: -11.7897 | BD7: 0.435133 | BG7: -1.8144 | BH7: 0.257925 | BK7: -1.65452 | BL7: 0.229776 | BO7: -1.59764 | BP7: 0.253021 | BS7: -9.07315 | BT7: -0.269669 | BW7: -1.65452 | BX7: 0.229731 | CA7: -0.510943 | CB7: -0.588179 | CE7: 1.15367 | CF7: -0.59566
C8: -0.993115 | D8: -0.523143 | G8: -0.423801 | H8: -0.382512 | K8: -1.02374 | L8: -0.418608 | O8: 0.0221331 | P8: -0.371753 | S8: -2.14354 | T8: -0.257934 | W8: -11.9008 | X8: 0.566156 | AA8: 0.16479 | AB8: -0.110352 | AE8: 1.87594 | AF8: 0.184154 | AI8: -0.169398 | AJ8: -0.497057 | AM8: 0.359481 | AN8: -0.442123 | AQ8: -2.58461 | AR8: -0.0696772 | AU8: -1.36264 | AV8: 0.0270545 | AY8: 0.870174 | AZ8: -0.33477 | BC8: -11.7093 | BD8: 0.456284 | BG8: -1.64081 | BH8: 0.198918 | BK8: -1.78787 | BL8: 0.27229 | BO8: -1.71621 | BP8: 0.293266 | BS8: -9.0775 | BT8: -0.269609 | BW8: -1.78787 | BX8: 0.272253 | CA8: -0.758293 | CB8: -0.65991 | CE8: 1.15065 | CF8: -0.59494
C9: -0.848546 | D9: -0.502732 | G9: -0.65915 | H9: -0.417385 | K9: -1.30847 | L9: -0.433387 | O9: -0.142987 | P9: -0.382028 | S9: -2.20238 | T9: -0.232594 | W9: -11.9013 | X9: 0.566241 | AA9: -0.0399006 | AB9: -0.168508 | AE9: 1.65614 | AF9: 0.236624 | AI9: 0.165958 | AJ9: -0.454289 | AM9: 0.0367304 | AN9: -0.486143 | AQ9: -2.58321 | AR9: 0.317286 | AU9: -1.5509 | AV9: 0.059405 | AY9: 1.03755 | AZ9: -0.290134 | BC9: -11.7087 | BD9: 0.456119 | BG9: -1.58038 | BH9: 0.177959 | BK9: -1.88723 | BL9: 0.317119 | BO9: -1.84682 | BP9: 0.340534 | BS9: -11.6432 | BT9: 0.417049 | BW9: -1.88723 | BX9: 0.317086 | CA9: -0.839367 | CB9: -0.684859 | CE9: 1.14788 | CF9: -0.594512
C10: -0.0815403 | D10: -0.34266 | G10: -0.864348 | H10: -0.453676 | K10: -1.43731 | L10: -0.442995 | O10: -0.377242 | P10: -0.390195 | S10: -2.28289 | T10: -0.178776 | W10: -11.9737 | X10: 0.561683 | AA10: -0.0964333 | AB10: -0.183519 | AE10: 1.58489 | AF10: 0.24186 | AI10: 0.171998 | AJ10: -0.453665 | AM10: -0.0389541 | AN10: -0.498085 | AQ10: -2.53146 | AR10: 0.632238 | AU10: -1.63616 | AV10: 0.0800152 | AY10: 1.21837 | AZ10: -0.227201 | BC10: -11.6838 | BD10: 0.431651 | BG10: -1.39257 | BH10: 0.140966 | BK10: -1.9677 | BL10: 0.355991 | BO10: -1.98978 | BP10: 0.407637 | BS10: -11.6683 | BT10: 0.454201 | BW10: -1.9677 | BX10: 0.355961 | CA10: -1.04499 | CB10: -0.785291 | CE10: 0.853315 | CF10: -0.524998
C11: -0.00986005 | D11: -0.324862 | G11: -1.00858 | H11: -0.473202 | K11: -1.48603 | L11: -0.445218 | O11: -0.489317 | P11: -0.397837 | S11: -2.30697 | T11: -0.169999 | W11: 10.6167 | X11: -0.0195576 | AA11: -0.149692 | AB11: -0.189518 | AE11: 1.26717 | AF11: 0.235638 | AI11: 0.189451 | AJ11: -0.451162 | AM11: -0.357735 | AN11: -0.55558 | AQ11: -2.52762 | AR11: 0.652862 | AU11: -1.78452 | AV11: 0.119417 | AY11: 1.31557 | AZ11: -0.195637 | BC11: -11.2944 | BD11: 0.0102212 | BG11: -1.18013 | BH11: 0.0959622 | BK11: -2.05907 | BL11: 0.400187 | BO11: -2.06918 | BP11: 0.4384 | BS11: -11.669 | BT11: 0.454523 | BW11: -2.05907 | BX11: 0.40016 | CA11: -1.12572 | CB11: -0.820388 | CE11: 0.72535 | CF11: -0.509766
C12: 0.0580915 | D12: -0.299835 | G12: -1.28003 | H12: -0.492911 | K12: -1.67384 | L12: -0.460652 | O12: -0.728879 | P12: -0.4118 | S12: -2.38188 | T12: -0.0733808 | W12: 10.7288 | X12: -0.0185508 | AA12: -0.357838 | AB12: -0.215775 | AE12: 1.26293 | AF12: 0.23559 | AI12: 0.553734 | AJ12: -0.399951 | AM12: -0.470639 | AN12: -0.575615 | AQ12: -2.48792 | AR12: 0.601745 | AU12: -1.87221 | AV12: 0.154429 | AY12: 1.5277 | AZ12: -0.103473 | BC12: -11.2946 | BD12: 0.0105109 | BG12: -1.04029 | BH12: 0.0733623 | BK12: -2.13388 | BL12: 0.443439 | BO12: -2.15844 | BP12: 0.484539 | BS12: -11.7504 | BT12: 0.432896 | BW12: -2.13388 | BX12: 0.443415 | CA12: -2.08712 | CB12: -2.12415 | CE12: 0.594782 | CF12: -0.490295
C13: 0.248439 | D13: -0.230057 | G13: -1.42245 | H13: -0.507075 | K13: -1.71768 | L13: -0.463998 | O13: -0.901392 | P13: -0.424754 | S13: -2.38685 | T13: -0.0652602 | W13: 10.7288 | X13: -0.0185521 | AA13: -0.514693 | AB13: -0.225786 | AE13: 1.25465 | AF13: 0.234183 | AI13: 0.672431 | AJ13: -0.377411 | AM13: -0.746748 | AN13: -0.621772 | AQ13: -2.43521 | AR13: 0.530838 | AU13: -2.00843 | AV13: 0.204222 | AY13: 1.59704 | AZ13: -0.0748672 | BC13: -11.2958 | BD13: 0.0118472 | BG13: -0.838582 | BH13: 0.0386642 | BK13: -2.23552 | BL13: 0.505949 | BO13: -2.2006 | BP13: 0.511598 | BS13: 16.0607 | BT13: 0.0343453 | BW13: -2.23552 | BX13: 0.505929 | CA13: -2.14731 | CB13: -2.27993 | CE13: 0.453241 | CF13: -0.481764
C14: 0.556138 | D14: -0.0961145 | G14: -1.48103 | H14: -0.512342 | K14: -1.90291 | L14: -0.473263 | O14: -1.021 | P14: -0.434342 | S14: -2.43102 | T14: 0.0612416 | W14: 10.8831 | X14: -0.0185219 | AA14: -0.732707 | AB14: -0.229934 | AE14: 0.940056 | AF14: 0.181303 | AI14: 1.00168 | AJ14: -0.315111 | AM14: -0.822149 | AN14: -0.642247 | AQ14: -2.42925 | AR14: 0.520313 | AU14: -2.09073 | AV14: 0.248595 | AY14: 1.63435 | AZ14: -0.0521175 | BC14: 15.2977 | BD14: 0.101434 | BG14: -0.619692 | BH14: 0.0176676 | BK14: -2.2414 | BL14: 0.509499 | BO14: -2.26729 | BP14: 0.562905 | BS14: 16.0602 | BT14: 0.0343138 | BW14: -2.2414 | BX14: 0.509479 | CA14: -2.18104 | CB14: -2.44657 | CE14: 0.330716 | CF14: -0.473207
C15: 0.706464 | D15: -0.0229961 | G15: -1.66722 | H15: -0.538427 | K15: -1.94914 | L15: -0.470498 | O15: -1.195 | P15: -0.453345 | S15: -2.47372 | T15: 0.186794 | W15: 10.8832 | X15: -0.0185195 | AA15: -0.941681 | AB15: -0.23313 | AE15: 0.748839 | AF15: 0.111738 | AI15: 1.04238 | AJ15: -0.307568 | AM15: -1.04027 | AN15: -0.695736 | AQ15: -2.39062 | AR15: 0.465725 | AU15: -2.15562 | AV15: 0.281886 | AY15: 1.8351 | AZ15: 0.072401 | BC15: 15.2963 | BD15: 0.101456 | BG15: -0.469239 | BH15: 0.0019078 | BK15: -2.25458 | BL15: 0.520259 | BO15: -2.3584 | BP15: 0.634416 | BS15: 15.9539 | BT15: 0.0399176 | BW15: -2.25458 | BX15: 0.520239 | CA15: -2.22731 | CB15: -2.73371 | CE15: 0.246581 | CF15: -0.469428
C16: 0.898385 | D16: 0.0734692 | G16: -1.737 | H16: -0.547579 | K16: -2.07203 | L16: -0.482092 | O16: -1.35309 | P16: -0.465705 | S16: -2.48239 | T16: 0.230192 | W16: 11.0391 | X16: -0.0148262 | AA16: -1.08122 | AB16: -0.231607 | AE16: 0.616322 | AF16: 0.0634348 | AI16: 1.08353 | AJ16: -0.297291 | AM16: -1.14881 | AN16: -0.730148 | AQ16: -2.3423 | AR16: 0.394666 | AU16: -2.2444 | AV16: 0.348602 | AY16: 1.83453 | AZ16: 0.0949491 | BC16: 15.2963 | BD16: 0.101456 | BG16: -0.266507 | BH16: -0.0037307 | BK16: -2.34475 | BL16: 0.595762 | BO16: -2.37034 | BP16: 0.639421 | BS16: 15.9534 | BT16: 0.0400031 | BW16: -2.34475 | BX16: 0.595746 | CA16: -2.28223 | CB16: -3.194 | CE16: -0.0476732 | CF16: -0.464992
C17: 0.983905 | D17: 0.113619 | G17: -1.89475 | H17: -0.572518 | K17: -2.09577 | L17: -0.482855 | O17: -1.45853 | P17: -0.478654 | S17: -2.53002 | T17: 0.483894 | W17: 11.0391 | X17: -0.0148252 | AA17: -1.29705 | AB17: -0.212013 | AE17: 0.490204 | AF17: 0.0218647 | AI17: 1.34984 | AJ17: -0.231109 | AM17: -1.32087 | AN17: -0.777291 | AQ17: -2.3314 | AR17: 0.379212 | AU17: -2.26841 | AV17: 0.366061 | AY17: 1.83297 | AZ17: 0.150307 | BC17: 15.1752 | BD17: 0.102509 | BG17: -0.210074 | BH17: -0.00642032 | BK17: -2.36361 | BL17: 0.606 | BO17: -2.4208 | BP17: 0.666656 | BS17: 15.8458 | BT17: 0.0428289 | BW17: -2.36361 | BX17: 0.605984 | CA17: -2.32124 | CB17: -3.49724 | CE17: -0.135714 | CF17: -0.465844
C18: -2.43927 | D18: -0.436179 | G18: -1.96356 | H18: -0.578483 | K18: -2.19759 | L18: -0.475744 | O18: -1.54662 | P18: -0.487867 | S18: -2.54916 | T18: 0.547836 | W18: 11.0392 | X18: -0.0148287 | AA18: -1.49235 | AB18: -0.200187 | AE18: 0.150648 | AF18: -0.0846153 | AI18: 1.46551 | AJ18: -0.176299 | AM18: -1.37686 | AN18: -0.798027 | AQ18: -2.24199 | AR18: 0.291424 | AU18: -2.29259 | AV18: 0.392295 | AY18: 1.75451 | AZ18: 0.185521 | BC18: 15.1751 | BD18: 0.102508 | BG18: -0.146501 | BH18: 0.000317677 | BK18: -2.42814 | BL18: 0.652632 | BO18: -2.45216 | BP18: 0.682976 | BS18: 15.8455 | BT18: 0.0427849 | BW18: -2.42814 | BX18: 0.652619 | CA18: -2.40303 | CB18: -4.36682 | CE18: -0.410377 | CF18: -0.472963
... C65: 1.48465 | D65: -0.185142 | G65: 1.09119 | H65: -0.254917 | K65: 1.44425 | L65: -0.213228 | O65: 0.669047 | P65: 0.0146348 | S65: -1.96528 | T65: -0.288954 | W65: 16.1831 | X65: 0.00775255 | AA65: 0.11398 | AB65: -0.428193 | AE65: -1.371 | AF65: -0.692777 | AI65: -1.75787 | AJ65: -0.0504471 | AM65: 0.12223 | AN65: -0.0545102 | AQ65: -2.3047 | AR65: -2.038 | AU65: 1.85133 | AV65: 0.0922481 | AY65: -2.18306 | AZ65: -1.90152 | BC65: 16.4959 | BD65: 0.0475774 | BG65: -2.02548 | BH65: -1.7713 | BK65: 1.51061 | BL65: -0.0885549 | BO65: 0.810563 | BP65: 0.227752 | BS65: 16.378 | BT65: 0.0479785 | BW65: 1.51061 | BX65: -0.0882378 | CA65: -1.45596 | CB65: 0.251497 | CE65: -0.546908 | CF65: -0.000338454
C66: 1.18253 | D66: -0.239437 | G66: 1.13161 | H66: -0.251072 | K66: 1.4993 | L66: -0.193473 | O66: 0.903781 | P66: 0.114379 | S66: -1.91363 | T66: -0.300976 | W66: 16.1836 | X66: 0.00776162 | AA66: 0.182063 | AB66: -0.421955 | AE66: -1.31965 | AF66: -0.677968 | AI66: -1.60438 | AJ66: -0.077205 | AM66: 0.480033 | AN66: 0.0525319 | AQ66: -2.1946 | AR66: -1.62484 | AU66: 1.85014 | AV66: 0.135462 | AY66: -2.15789 | AZ66: -1.83357 | BC66: 16.3908 | BD66: 0.038175 | BG66: -1.91398 | BH66: -1.56641 | BK66: 1.594 | BL66: -0.0545882 | BS66: 16.3788 | BT66: 0.0479612 | BW66: 1.594 | BX66: -0.0542781 | CA66: -1.61987 | CB66: 0.299026 | CE66: -0.689254 | CF66: 0.0292861
C67: 1.16181 | D67: -0.243065 | G67: 1.20829 | H67: -0.238002 | K67: 1.69856 | L67: -0.11015 | O67: 0.987039 | P67: 0.150203 | S67: -1.74123 | T67: -0.30943 | W67: 16.2936 | X67: 0.0201947 | AA67: 0.395498 | AB67: -0.393837 | AE67: -1.14213 | AF67: -0.638925 | AI67: -1.51716 | AJ67: -0.0936788 | AM67: 0.588817 | AN67: 0.0875668 | AQ67: -2.15229 | AR67: -1.51757 | AU67: 1.84951 | AV67: 0.160124 | AY67: -2.12771 | AZ67: -1.77168 | BC67: 16.3899 | BD67: 0.0382079 | BG67: -1.74824 | BH67: -1.36112 | BK67: 1.65251 | BL67: -0.0269173 | BO67: -1.59764 | BP67: 0.253021 | BS67: 16.4841 | BT67: 0.0486863 | BW67: 1.65251 | BX67: -0.026617 | CA67: -1.68534 | CB67: 0.323593 | CE67: -0.907378 | CF67: 0.0683995
C68: 1.13899 | D68: -0.244901 | G68: 1.44216 | H68: -0.203834 | K68: 1.81258 | L68: -0.0274232 | O68: 1.02402 | P68: 0.158095 | S68: -1.70134 | T68: -0.311277 | W68: 16.2941 | X68: 0.0202436 | AA68: 0.551209 | AB68: -0.374503 | AE68: -1.03704 | AF68: -0.615304 | AI68: -1.32635 | AJ68: -0.115326 | AM68: 0.800188 | AN68: 0.159117 | AQ68: -2.04884 | AR68: -1.35635 | AU68: 1.84951 | AV68: 0.160124 | AY68: -2.04394 | AZ68: -1.58207 | BC68: 16.2845 | BD68: 0.039084 | BG68: -1.73885 | BH68: -1.34925 | BK68: 1.78307 | BL68: 0.0296456 | BO68: -1.42123 | BP68: 0.211577 | BS68: 16.4848 | BT68: 0.0486862 | BW68: 1.78307 | BX68: 0.0299111 | CA68: -1.82792 | CB68: 0.379262 | CE68: -1.11487 | CF68: 0.125233
C69: 0.873998 | D69: -0.268714 | G69: 1.6393 | H69: -0.122393 | K69: 1.93116 | L69: 0.0448596 | O69: 1.31649 | P69: 0.214142 | S69: -1.50926 | T69: -0.316812 | W69: 16.4042 | X69: 0.0342266 | AA69: 0.686081 | AB69: -0.353078 | AE69: -1.03704 | AF69: -0.615304 | AI69: -1.108 | AJ69: -0.139011 | AM69: 0.939721 | AN69: 0.206473 | AQ69: -2.04785 | AR69: -1.35492 | AU69: 1.6827 | AV69: 0.211191 | AY69: -1.98618 | AZ69: -1.48766 | BC69: 16.2836 | BD69: 0.0390389 | BG69: -1.72917 | BH69: -1.33966 | BK69: 1.78173 | BL69: 0.0647965 | BO69: -1.20133 | BP69: 0.152448 | BS69: 16.5902 | BT69: 0.0472894 | BW69: 1.78173 | BX69: 0.0649605 | CA69: -1.93035 | CB69: 0.42973 | CE69: -1.23932 | CF69: 0.159339
C70: 1.34611 | D70: 0.187776 | G70: 1.71766 | H70: -0.0904298 | K70: 1.97151 | L70: 0.0790497 | O70: 1.40363 | P70: 0.222975 | S70: -1.46572 | T70: -0.319114 | W70: 16.4049 | X70: 0.0342113 | AA70: 0.911729 | AB70: -0.320885 | AE70: -0.812097 | AF70: -0.563955 | AI70: -1.108 | AJ70: -0.139011 | AM70: 1.01808 | AN70: 0.217334 | AQ70: -2.04722 | AR70: -1.35438 | AU70: 1.58961 | AV70: 0.237422 | AY70: -1.90146 | AZ70: -1.37196 | BC70: 16.1778 | BD70: 0.043863 | BG70: -1.55413 | BH70: -1.14834 | BK70: 1.78001 | BL70: 0.095293 | BO70: -1.06645 | BP70: 0.123264 | BS70: 16.5909 | BT70: 0.0472576 | BW70: 1.78001 | BX70: 0.095336 | CA70: -2.0115 | CB70: 0.467559 | CE70: -1.46105 | CF70: 0.226691
C71: 1.33617 | D71: 0.185616 | G71: 1.78433 | H71: -0.0471933 | K71: 1.97172 | L71: 0.0947241 | O71: 1.67334 | P71: 0.232444 | S71: -1.34289 | T71: -0.320001 | W71: 16.515 | X71: 0.02002 | AA71: 1.01774 | AB71: -0.30155 | AE71: -0.741693 | AF71: -0.54809 | AI71: -0.958242 | AJ71: -0.149232 | AM71: 0.455333 | AN71: -0.42444 | AQ71: -1.92269 | AR71: -1.22277 | AU71: 1.43804 | AV71: 0.244946 | AY71: -1.72433 | AZ71: -1.1919 | BC71: 16.1772 | BD71: 0.043892 | BG71: -1.42477 | BH71: -1.06192 | BK71: -1.65452 | BL71: 0.229776 | BO71: -0.862574 | BP71: 0.0825666 | BS71: 16.6964 | BT71: 0.0437097 | BW71: -1.65452 | BX71: 0.229731 | CA71: -2.11998 | CB71: 0.52938 | CE71: -1.62629 | CF71: 0.282298
C72: 1.27417 | D72: 0.173213 | G72: 1.98191 | H72: 0.085713 | K72: 1.97248 | L72: 0.158107 | O72: 1.72924 | P72: 0.234574 | S72: -1.05313 | T72: -0.325997 | W72: 16.5155 | X72: 0.0200022 | AA72: 1.31075 | AB72: -0.242039 | AE72: -0.537755 | AF72: -0.525863 | AI72: -0.760598 | AJ72: -0.159449 | AM72: 0.72492 | AN72: -0.365919 | AQ72: -1.73925 | AR72: -1.0714 | AU72: 1.25456 | AV72: 0.257667 | AY72: -1.70159 | AZ72: -1.17231 | BC72: 16.0705 | BD72: 0.0448652 | BG72: -1.34514 | BH72: -1.00699 | BK72: -1.58925 | BL72: 0.207352 | BO72: -0.64231 | BP72: 0.0545182 | BS72: 16.6969 | BT72: 0.0436669 | BW72: -1.58925 | BX72: 0.207303 | CA72: -2.0188 | CB72: -1.93031 | CE72: -1.70395 | CF72: 0.311251
C73: 0.983905 | D73: 0.113619 | G73: 1.98257 | H73: 0.13516 | K73: 1.82203 | L73: 0.225562 | O73: 1.75165 | P73: 0.228028 | S73: -0.913189 | T73: -0.31918 | W73: 16.6257 | X73: 0.00338932 | AA73: 1.40246 | AB73: -0.212227 | AE73: -0.374121 | AF73: -0.502827 | AI73: -0.539135 | AJ73: -0.158564 | AM73: 0.839108 | AN73: -0.341756 | AQ73: -1.4896 | AR73: -0.907805 | AU73: 1.05372 | AV73: 0.234512 | AY73: -1.68198 | AZ73: -1.15707 | BC73: 16.0699 | BD73: 0.0448855 | BG73: -1.19468 | BH73: -0.935324 | BK73: -1.40415 | BL73: 0.170814 | BO73: -0.495743 | BP73: 0.0348804 | BS73: 16.8027 | BT73: 0.0191368 | BW73: -1.40415 | BX73: 0.170756 | CA73: -2.08712 | CB73: -2.12415 | CE73: -1.83806 | CF73: 0.369975
C74: -0.269593 | D74: -0.395274 | G74: 1.98319 | H74: 0.177413 | K74: 1.80946 | L74: 0.229573 | O74: 1.87679 | P74: 0.201334 | S74: -0.703923 | T74: -0.302745 | W74: 16.6262 | X74: 0.00320573 | AA74: 1.58436 | AB74: -0.140261 | AE74: -0.207511 | AF74: -0.481012 | AI74: -0.386429 | AJ74: -0.155657 | AM74: 1.02932 | AN74: -0.306206 | AQ74: -1.73764 | AR74: -1.07029 | AU74: 0.885164 | AV74: 0.21482 | AY74: -1.4985 | AZ74: -1.01724 | BC74: 15.963 | BD74: 0.0402957 | BG74: -1.06835 | BH74: -0.877249 | BK74: -1.19091 | BL74: 0.122575 | BO74: -0.296829 | BP74: 0.0293638 | BS74: 16.8031 | BT74: 0.0189307 | BW74: -1.19091 | BX74: 0.122501 | CA74: -1.94419 | CB74: -1.75713 | CE74: -1.9378 | CF74: 0.419895
C75: -0.0815403 | D75: -0.34266 | G75: 1.81355 | H75: 0.213473 | K75: 1.80161 | L75: 0.236932 | O75: 1.96117 | P75: 0.181748 | S75: -0.4813 | T75: -0.289714 | W75: 16.7364 | X75: -0.0595463 | AA75: 1.68829 | AB75: -0.0758621 | AE75: -0.10885 | AF75: -0.46923 | AI75: -0.179928 | AJ75: -0.137754 | AM75: 1.23866 | AN75: -0.25117 | AQ75: -1.3566 | AR75: -0.858835 | AU75: 0.700642 | AV75: 0.156758 | AY75: -1.3828 | AZ75: -0.943361 | BC75: 15.9626 | BD75: 0.0402367 | BG75: -0.841185 | BH75: -0.785979 | BK75: -1.05381 | BL75: 0.096084 | BO75: -0.237928 | BP75: 0.026952 | BS75: 16.8843 | BT75: -0.0368621 | BW75: -1.05381 | BX75: 0.0960012 | CA75: -1.83142 | CB75: -1.50152 | CE75: -2.02278 | CF75: 0.461717
C76: -0.405902 | D76: -0.423804 | G76: 1.78164 | H76: 0.21975 | K76: 1.77944 | L76: 0.235572 | O76: 1.96117 | P76: 0.181748 | S76: -0.328812 | T76: -0.272034 | W76: 16.7367 | X76: -0.059787 | AA76: 1.76999 | AB76: -0.0178959 | AE76: 0.172237 | AF76: -0.436614 | AI76: -0.125106 | AJ76: -0.133849 | AM76: 1.35102 | AN76: -0.222545 | AQ76: -1.20506 | AR76: -0.791398 | AU76: 0.560595 | AV76: 0.113259 | AY76: -1.30758 | AZ76: -0.895781 | BC76: 15.8554 | BD76: 0.0302038 | BG76: -0.755395 | BH76: -0.749311 | BK76: -0.850707 | BL76: 0.055007 | BO76: -0.173048 | BP76: 0.0344254 | BS76: 17.1501 | BT76: 0.285212 | BW76: -0.850707 | BX76: 0.0549082 | CA76: -1.75212 | CB76: -1.37499 | CE76: -2.1161 | CF76: 0.520458
C77: -0.643818 | D77: -0.460374 | G77: 1.6305 | H77: 0.213671 | K77: 1.41002 | L77: 0.218162 | O77: 1.96053 | P77: 0.0890307 | S77: -0.122591 | T77: -0.235839 | W77: 16.822 | X77: -0.122856 | AA77: 1.92349 | AB77: 0.106066 | AE77: 0.243354 | AF77: -0.429829 | AI77: -0.06645 | AJ77: -0.119747 | AM77: 1.44339 | AN77: -0.174975 | AQ77: -1.09598 | AR77: -0.758491 | AU77: 0.455007 | AV77: 0.0829699 | AY77: -1.14695 | AZ77: -0.841582 | BC77: 15.8551 | BD77: 0.030187 | BG77: -0.404775 | BH77: -0.648527 | BK77: -0.630711 | BL77: 0.0298341 | BO77: 0.0218244 | BP77: 0.0545967 | BS77: 17.1392 | BT77: 0.256885 | BW77: -0.630711 | BX77: 0.0297155 | CA77: -1.63191 | CB77: -1.21098 | CE77: -2.1632 | CF77: 0.546791
C78: -0.848546 | D78: -0.502732 | G78: 1.41027 | H78: 0.205417 | K78: 1.24523 | L78: 0.194308 | O78: 1.96051 | P78: 0.0850268 | S78: -0.0676424 | T78: -0.22689 | W78: 17.109 | X78: 0.248592 | AA78: 1.92394 | AB78: 0.106414 | AE78: 0.397842 | AF78: -0.40874 | AI78: 0.13646 | AJ78: -0.065098 | AM78: 1.64756 | AN78: -0.0687309 | AQ78: -0.843396 | AR78: -0.688534 | AU78: 0.0936635 | AV78: -0.0154564 | AY78: -1.0576 | AZ78: -0.805689 | BC78: 15.7484 | BD78: 0.0245897 | BG78: -0.356231 | BH78: -0.633842 | BK78: -0.482564 | BL78: 0.0143239 | BO78: 0.392725 | BP78: 0.125772 | BS78: 17.1501 | BT78: 0.285278 | BW78: -0.482564 | BX78: 0.0141905 | CA78: -1.57683 | CB78: -1.13362 | CE78: -2.23065 | CF78: 0.593747
... C81: -1.47051 | D81: -0.577741 | G81: 1.01368 | H81: 0.131574 | K81: -0.874594 | L81: -0.407287 | O81: 1.45331 | P81: -0.2053 | S81: 0.508574 | T81: -0.0335196 | W81: 17.0681 | X81: 0.170258 | AA81: 1.92367 | AB81: 0.174551 | AE81: 0.870112 | AF81: -0.332207 | AI81: 0.807999 | AJ81: 0.146144 | AM81: 1.88097 | AN81: 0.165684 | AQ81: -0.387768 | AR81: -0.583457 | AU81: -0.235381 | AV81: -0.0639479 | AY81: -0.752624 | AZ81: -0.704368 | BC81: 15.4106 | BD81: 0.016421 | BG81: 0.384842 | BH81: -0.456597 | BK81: -0.158181 | BL81: 0.0126392 | BO81: 0.810563 | BP81: 0.227752 | BS81: 17.1253 | BT81: 0.294995 | BW81: -0.158181 | BX81: 0.0124734 | CA81: -1.26941 | CB81: -0.909472 | CE81: -2.37241 | CF81: 0.687344
C82: -1.65256 | D82: -0.611945 | G82: 0.954052 | H82: 0.105583 | K82: -0.674281 | L82: -0.383944 | O82: 1.43329 | P82: -0.213309 | S82: 0.656161 | T82: 0.026052 | W82: 17.1197 | X82: 0.307428 | AA82: 1.908 | AB82: 0.17832 | AE82: 1.00502 | AF82: -0.308223 | AI82: 0.970605 | AJ82: 0.201278 | AM82: 1.88089 | AN82: 0.170738 | AQ82: -0.279265 | AR82: -0.561044 | AU82: -0.428421 | AV82: -0.0707177 | AY82: -0.494511 | AZ82: -0.644792 | BC82: 15.3074 | BD82: 0.00955257 | BG82: 0.411887 | BH82: -0.450962 | BK82: 0.036223 | BL82: 0.0348791 | BS82: 17.0865 | BT82: 0.230841 | BW82: 0.036223 | BX82: 0.0346872 | CA82: -1.12572 | CB82: -0.820388 | CE82: -2.41476 | CF82: 0.683899
C83: -1.73008 | D83: -0.630792 | G83: 0.694202 | H83: -0.0129157 | K83: -0.440396 | L83: -0.359628 | O83: 1.40234 | P83: -0.218491 | S83: 0.952547 | T83: 0.150839 | W83: 17.106 | X83: 0.26484 | AA83: 1.69637 | AB83: 0.240706 | AE83: 1.21435 | AF83: -0.267634 | AI83: 1.05906 | AJ83: 0.218108 | AM83: 1.82992 | AN83: 0.183098 | AQ83: -0.279265 | AR83: -0.561044 | AU83: -0.571221 | AV83: -0.0660835 | AY83: -0.310477 | AZ83: -0.600272 | BC83: 15.3073 | BD83: 0.00954007 | BG83: 0.425856 | BH83: -0.447242 | BK83: 0.410424 | BL83: 0.117576 | BO83: 1.65692 | BP83: -0.0494576 | BS83: 17.0393 | BT83: 0.144033 | BW83: 0.410424 | BX83: 0.117349 | CA83: -0.0380646 | CB83: -0.507339 | CE83: -2.45148 | CF83: 0.681518
C84: -1.88024 | D84: -0.666545 | G84: 0.547043 | H84: -0.0798748 | K84: -0.299385 | L84: -0.339202 | O84: 1.15194 | P84: -0.264338 | S84: 0.977296 | T84: 0.161291 | W84: 17.1198 | X84: 0.307517 | AA84: 1.63545 | AB84: 0.241066 | AE84: 1.44073 | AF84: -0.196561 | AI84: 1.36899 | AJ84: 0.257164 | AM84: 1.57186 | AN84: 0.248246 | AQ84: 0.0422077 | AR84: -0.503202 | AU84: -0.800687 | AV84: -0.0543803 | AY84: -0.104454 | AZ84: -0.551839 | BC84: 15.1942 | BD84: -0.000248979 | BG84: 0.532911 | BH84: -0.417534 | BK84: 0.502136 | BL84: 0.138686 | BO84: 1.61626 | BP84: -0.06194 | BW84: 0.502136 | BX84: 0.138445 | CA84: -0.133066 | CB84: -0.520014 | CE84: -2.45639 | CF84: 0.680375
C85: -1.97262 | D85: -0.687858 | G85: 0.234662 | H85: -0.21725 | K85: -0.110283 | L85: -0.298903 | O85: 1.03571 | P85: -0.279168 | S85: 0.989052 | T85: 0.163722 | W85: 17.1208 | X85: 0.310721 | AA85: 1.41048 | AB85: 0.240116 | AE85: 1.50562 | AF85: -0.168944 | AI85: 1.38798 | AJ85: 0.257775 | AM85: 1.48477 | AN85: 0.252599 | AQ85: 0.386599 | AR85: -0.451097 | AU85: -0.997123 | AV85: -0.0357733 | AY85: 0.0801987 | AZ85: -0.510592 | BC85: 15.1941 | BD85: -0.000250004 | BG85: 0.821351 | BH85: -0.338748 | BK85: 0.613293 | BL85: 0.169565 | BO85: 1.49721 | BP85: -0.106643 | BW85: 0.613293 | BX85: 0.169311 | CA85: -0.407005 | CB85: -0.566146 | CE85: -2.49553 | CF85: 0.562358
C86: -2.05001 | D86: -0.697466 | G86: 0.045106 | H86: -0.291841 | K86: -0.0387775 | L86: -0.284556 | O86: 0.844017 | P86: -0.305271 | S86: 1.31017 | T86: 0.22215 | AA86: 1.29824 | AB86: 0.231896 | AE86: 1.66038 | AF86: -0.0694279 | AI86: 1.42301 | AJ86: 0.256273 | AM86: 1.25238 | AN86: 0.250191 | AQ86: 0.437481 | AR86: -0.444052 | AU86: -1.14563 | AV86: -0.0195753 | AY86: 0.262373 | AZ86: -0.470401 | BC86: 15.1541 | BD86: -7.16126e-05 | BG86: 0.862387 | BH86: -0.328208 | BK86: 0.826011 | BL86: 0.229031 | BO86: 1.44443 | BP86: -0.12621 | BW86: 0.826011 | BX86: 0.228756 | CA86: -0.510943 | CB86: -0.588179 | CE86: -2.52597 | CF86: 0.466723
C87: -2.12578 | D87: -0.705213 | G87: -0.0243201 | H87: -0.313801 | K87: 0.0338135 | L87: -0.260922 | O87: 0.619529 | P87: -0.329489 | S87: 1.38644 | T87: 0.228267 | AA87: 0.971489 | AB87: 0.178194 | AE87: 1.74307 | AF87: -0.0169681 | AI87: 1.65142 | AJ87: 0.247963 | AM87: 1.01808 | AN87: 0.217334 | AQ87: 0.464936 | AR87: -0.437498 | AY87: 0.556504 | AZ87: -0.409441 | BG87: 1.17365 | BH87: -0.243156 | BK87: 1.01407 | BL87: 0.24388 | BO87: 1.4291 | BP87: -0.132521 | BW87: 1.01407 | BX87: 0.243604 | CA87: -0.0380646 | CB87: -0.507339 | CE87: -2.5312 | CF87: 0.341471
C88: -2.21382 | D88: -0.733535 | G88: -0.0952967 | H88: -0.325314 | K88: 0.220814 | L88: -0.192463 | O88: 0.481098 | P88: -0.343775 | S88: 1.64012 | T88: 0.232596 | AA88: 0.951594 | AB88: 0.174312 | AE88: 1.76613 | AF88: -0.000121005 | AI88: 1.85298 | AJ88: 0.197341 | AQ88: 0.684572 | AR88: -0.387738 | AY88: 0.578329 | AZ88: -0.405161 | BG88: 1.23782 | BH88: -0.221681 | BK88: 1.15693 | BL88: 0.254471 | BO88: 1.17197 | BP88: -0.222874 | BW88: 1.15693 | BX88: 0.254187 | CA88: 0.243666 | CB88: -0.482402 | CE88: -2.56431 | CF88: -0.353688
C89: -2.25585 | D89: -0.741667 | G89: -0.284532 | H89: -0.361455 | K89: 0.564885 | L89: -0.0446894 | O89: 0.235894 | P89: -0.360068 | S89: 1.70999 | T89: 0.234419 | AA89: 0.909385 | AB89: 0.158735 | AE89: 1.91057 | AF89: 0.104502 | AI89: 1.89573 | AJ89: 0.186333 | AQ89: 0.882077 | AR89: -0.343083 | AY89: 0.593136 | AZ89: -0.401708 | BK89: 1.33014 | BL89: 0.239786 | BO89: 1.13556 | BP89: -0.234183 | BW89: 1.33014 | BX89: 0.239517 | CA89: 0.338306 | CB89: -0.475183 | CE89: -2.57117 | CF89: -1.25158
C90: -2.3231 | D90: -0.736535 | K90: 0.681728 | L90: 0.00680544 | S90: 1.73789 | T90: 0.227093 | AA90: 0.909385 | AB90: 0.158735 | AE90: 1.91055 | AF90: 0.107122 | AI90: 1.89655 | AJ90: 0.106663 | AQ90: 0.911836 | AR90: -0.337062 | BK90: 1.42712 | BL90: 0.233548 | BO90: 0.823065 | BP90: -0.322308 | BS90: 1.76463 | BT90: -0.0158807 | BW90: 1.42712 | BX90: 0.233286 | CA90: 0.479891 | CB90: -0.471198 | CE90: -2.55695 | CF90: -2.65026
...

Sheet Hoja1

Sheet Esf_X_(y=3m)
A2: Entre el encastre y el motor
C3: X | D3: Y | G3: X | H3: Y | K3: X | L3: Y | O3: X | P3: Y | S3: X | T3: Y | W3: X | X3: Y | AA3: X | AB3: Y | AE3: X | AF3: Y | AI3: X | AJ3: Y | AM3: X | AN3: Y | AQ3: X | AR3: Y | AU3: X | AV3: Y | AY3: X | AZ3: Y | BC3: X | BD3: Y | BG3: X | BH3: Y | BK3: X | BL3: Y | BO3: X | BP3: Y | BS3: X | BT3: Y | BW3: X | BX3: Y | CA3: X | CB3: Y | CE3: X | CF3: Y
D4: Pa
B5: alfa | F5: alfa | J5: alfa | N5: alfa | R5: alfa | V5: alfa | Z5: alfa | AD5: alfa | AH5: alfa | AL5: alfa | AP5: alfa | AT5: alfa | AX5: alfa | BB5: alfa | BF5: alfa | BJ5: alfa | BN5: alfa | BR5: alfa | BV5: alfa | BZ5: alfa | CD5: alfa
B6: -5 | F6: -4 | J6: -3 | N6: -2 | R6: -1 | V6: 0 | Z6: 1 | AD6: 2 | AH6: 3 | AL6: 4 | AP6: 5 | AT6: 6 | AX6: 7 | BB6: 8 | BF6: 9 | BJ6: 10 | BN6: 11 | BR6: 12 | BV6: 13 | BZ6: 14 | CD6: 15
B7: a | C7: -1.25569 | D7: 7.89529 | G7: -0.284532 | H7: 7.0214 | K7: -0.874594 | L7: 7.24902 | O7: 0.235894 | P7: 7.99539 | S7: -2.07403 | T7: 7.66275 | W7: -11.8791 | X7: 2.5321 | AA7: 0.496072 | AB7: 6.092 | AE7: 1.90999 | AF7: 2.74693 | AI7: -0.193693 | AJ7: 8.6355 | AM7: 0.455333 | AN7: 9.61063 | AQ7: -2.57986 | AR7: 2.01985 | AU7: -1.14563 | AV7: 5.63759 | AY7: 0.593136 | AZ7: 8.47518 | BC7: -11.7897 | BD7: 4.25429 | BG7: -1.8144 | BH7: 4.43695 | BK7: -1.65452 | BL7: 4.39579 | BO7: -1.59764 | BP7: 5.12519 | BS7: -9.07315 | BT7: 12.211 | BW7: -1.65452 | BX7: 4.39577 | CA7: -0.510943 | CB7: 8.47593 | CE7: 1.15367 | CF7: -1.49862
B8: b | C8: -0.993115 | D8: 7.67842 | G8: -0.423801 | H8: 7.0485 | K8: -1.02374 | L8: 7.25755 | O8: 0.0221331 | P8: 7.56913 | S8: -2.14354 | T8: 7.22308 | W8: -11.9008 | X8: 2.48105 | AA8: 0.16479 | AB8: 6.19472 | AE8: 1.87594 | AF8: 3.16587 | AI8: -0.169398 | AJ8: 8.57808 | AM8: 0.359481 | AN8: 9.63542 | AQ8: -2.58461 | AR8: 1.08054 | AU8: -1.36264 | AV8: 5.24463 | AY8: 0.870174 | AZ8: 8.25593 | BC8: -11.7093 | BD8: 3.79483 | BG8: -1.64081 | BH8: 4.72854 | BK8: -1.78787 | BL8: 4.36571 | BO8: -1.71621 | BP8: 5.03775 | BS8: -9.0775 | BT8: 12.2313 | BW8: -1.78787 | BX8: 4.36566 | CA8: -0.758293 | CB8: 9.14698 | CE8: 1.15065 | CF8: -1.52579
C9: -0.848546 | D9: 7.60951 | G9: -0.65915 | H9: 7.64416 | K9: -1.30847 | L9: 7.0298 | O9: -0.142987 | P9: 7.41925 | S9: -2.20238 | T9: 7.33702 | W9: -11.9013 | X9: 2.48218 | AA9: -0.0399006 | AB9: 5.98063 | AE9: 1.65614 | AF9: 6.18437 | AI9: 0.165958 | AJ9: 8.86869 | AM9: 0.0367304 | AN9: 9.43284 | AQ9: -2.58321 | AR9: 0.683882 | AU9: -1.5509 | AV9: 4.94663 | AY9: 1.03755 | AZ9: 8.1323 | BC9: -11.7087 | BD9: 3.79459 | BG9: -1.58038 | BH9: 4.76451 | BK9: -1.88723 | BL9: 4.17317 | BO9: -1.84682 | BP9: 4.79041 | BS9: -11.6432 | BT9: 4.04206 | BW9: -1.88723 | BX9: 4.1731 | CA9: -0.839367 | CB9: 9.50717 | CE9: 1.14788 | CF9: -1.53937
C10: -0.0815403 | D10: 8.01441 | G10: -0.864348 | H10: 7.84843 | K10: -1.43731 | L10: 7.06168 | O10: -0.377242 | P10: 7.17712 | S10: -2.28289 | T10: 6.64138 | W10: -11.9737 | X10: 3.01655 | AA10: -0.0964333 | AB10: 5.95057 | AE10: 1.58489 | AF10: 6.24007 | AI10: 0.171998 | AJ10: 8.88432 | AM10: -0.0389541 | AN10: 9.41222 | AQ10: -2.53146 | AR10: 0.694931 | AU10: -1.63616 | AV10: 4.79303 | AY10: 1.21837 | AZ10: 7.81371 | BC10: -11.6838 | BD10: 3.84035 | BG10: -1.39257 | BH10: 4.83868 | BK10: -1.9677 | BL10: 4.0482 | BO10: -1.98978 | BP10: 4.01798 | BS10: -11.6683 | BT10: 3.88784 | BW10: -1.9677 | BX10: 4.04811 | CA10: -1.04499 | CB10: 10.2195 | CE10: 0.853315 | CF10: -2.28953
C11: -0.00986005 | D11: 8.04001 | G11: -1.00858 | H11: 7.72022 | K11: -1.48603 | L11: 7.05965 | O11: -0.489317 | P11: 7.23786 | S11: -2.30697 | T11: 6.61183 | W11: 10.6167 | X11: 11.7104 | AA11: -0.149692 | AB11: 5.88463 | AE11: 1.26717 | AF11: 5.89266 | AI11: 0.189451 | AJ11: 8.88931 | AM11: -0.357735 | AN11: 9.37095 | AQ11: -2.52762 | AR11: 0.701347 | AU11: -1.78452 | AV11: 4.62374 | AY11: 1.31557 | AZ11: 7.63094 | BC11: -11.2944 | BD11: 6.06708 | BG11: -1.18013 | BH11: 4.97634 | BK11: -2.05907 | BL11: 3.78793 | BO11: -2.06918 | BP11: 3.54121 | BS11: -11.669 | BT11: 3.88612 | BW11: -2.05907 | BX11: 3.78786 | CA11: -1.12572 | CB11: 10.5902 | CE11: 0.72535 | CF11: -2.44204
C12: 0.0580915 | D12: 7.77789 | G12: -1.28003 | H12: 7.40474 | K12: -1.67384 | L12: 6.97771 | O12: -0.728879 | P12: 7.03189 | S12: -2.38188 | T12: 5.69147 | W12: 10.7288 | X12: 11.5727 | AA12: -0.357838 | AB12: 6.00828 | AE12: 1.26293 | AF12: 5.893 | AI12: 0.553734 | AJ12: 9.00702 | AM12: -0.470639 | AN12: 9.26886 | AQ12: -2.48792 | AR12: 1.03801 | AU12: -1.87221 | AV12: 4.31714 | AY12: 1.5277 | AZ12: 7.1335 | BC12: -11.2946 | BD12: 6.06658 | BG12: -1.04029 | BH12: 5.15846 | BK12: -2.13388 | BL12: 3.45604 | BO12: -2.15844 | BP12: 3.15783 | BS12: -11.7504 | BT12: 4.07135 | BW12: -2.13388 | BX12: 3.45596 | CA12: -2.08712 | CB12: 16.2394 | CE12: 0.594782 | CF12: -2.02712
C13: 0.248439 | D13: 7.33481 | G13: -1.42245 | H13: 7.1961 | K13: -1.71768 | L13: 6.97645 | O13: -0.901392 | P13: 6.77163 | S13: -2.38685 | T13: 5.63669 | W13: 10.7288 | X13: 11.5728 | AA13: -0.514693 | AB13: 5.99339 | AE13: 1.25465 | AF13: 5.88553 | AI13: 0.672431 | AJ13: 8.92529 | AM13: -0.746748 | AN13: 9.40935 | AQ13: -2.43521 | AR13: 1.51368 | AU13: -2.00843 | AV13: 4.03692 | AY13: 1.59704 | AZ13: 7.01416 | BC13: -11.2958 | BD13: 6.05933 | BG13: -0.838582 | BH13: 5.48433 | BK13: -2.23552 | BL13: 3.02245 | BO13: -2.2006 | BP13: 2.99479 | BS13: 16.0607 | BT13: 9.82944 | BW13: -2.23552 | BX13: 3.02238 | CA13: -2.14731 | CB13: 17.4206 | CE13: 0.453241 | CF13: -1.80958
C14: 0.556138 | D14: 7.19098 | G14: -1.48103 | H14: 7.13024 | K14: -1.90291 | L14: 7.03761 | O14: -1.021 | P14: 6.76158 | S14: -2.43102 | T14: 4.44236 | W14: 10.8831 | X14: 11.8168 | AA14: -0.732707 | AB14: 6.2489 | AE14: 0.940056 | AF14: 5.78169 | AI14: 1.00168 | AJ14: 8.46757 | AM14: -0.822149 | AN14: 9.51833 | AQ14: -2.42925 | AR14: 1.58153 | AU14: -2.09073 | AV14: 3.77141 | AY14: 1.63435 | AZ14: 6.33382 | BC14: 15.2977 | BD14: 8.49421 | BG14: -0.619692 | BH14: 5.57191 | BK14: -2.2414 | BL14: 2.99618 | BO14: -2.26729 | BP14: 2.69277 | BS14: 16.0602 | BT14: 9.83057 | BW14: -2.2414 | BX14: 2.99611 | CA14: -2.18104 | CB14: 18.0569 | CE14: 0.330716 | CF14: -1.30502
C15: 0.706464 | D15: 7.06207 | G15: -1.66722 | H15: 6.82716 | K15: -1.94914 | L15: 6.9349 | O15: -1.195 | P15: 6.88105 | S15: -2.47372 | T15: 3.41261 | W15: 10.8832 | X15: 11.8167 | AA15: -0.941681 | AB15: 6.36144 | AE15: 0.748839 | AF15: 5.90889 | AI15: 1.04238 | AJ15: 8.43868 | AM15: -1.04027 | AN15: 9.63534 | AQ15: -2.39062 | AR15: 1.96515 | AU15: -2.15562 | AV15: 3.61869 | AY15: 1.8351 | AZ15: 2.52583 | BC15: 15.2963 | BD15: 8.49508 | BG15: -0.469239 | BH15: 5.71775 | BK15: -2.25458 | BL15: 2.90572 | BO15: -2.3584 | BP15: 1.99425 | BS15: 15.9539 | BT15: 9.60948 | BW15: -2.25458 | BX15: 2.90565 | CA15: -2.22731 | CB15: 19.0061 | CE15: 0.246581 | CF15: -1.10482
C16: 0.898385 | D16: 6.86504 | G16: -1.737 | H16: 6.92259 | K16: -2.07203 | L16: 6.79942 | O16: -1.35309 | P16: 6.88891 | S16: -2.48239 | T16: 3.1921 | W16: 11.0391 | X16: 11.6858 | AA16: -1.08122 | AB16: 6.33756 | AE16: 0.616322 | AF16: 6.19889 | AI16: 1.08353 | AJ16: 8.44942 | AM16: -1.14881 | AN16: 9.77091 | AQ16: -2.3423 | AR16: 2.47055 | AU16: -2.2444 | AV16: 3.13926 | AY16: 1.83453 | AZ16: 2.60188 | BC16: 15.2963 | BD16: 8.49509 | BG16: -0.266507 | BH16: 5.6056 | BK16: -2.34475 | BL16: 2.29041 | BO16: -2.37034 | BP16: 1.91871 | BS16: 15.9534 | BT16: 9.60667 | BW16: -2.34475 | BX16: 2.2903 | CA16: -2.28223 | CB16: 20.4716 | CE16: -0.0476732 | CF16: 0.615141
C17: 0.983905 | D17: 6.78515 | G17: -1.89475 | H17: 6.84622 | K17: -2.09577 | L17: 6.65272 | O17: -1.45853 | P17: 6.94917 | S17: -2.53002 | T17: 2.31442 | W17: 11.0391 | X17: 11.6856 | AA17: -1.29705 | AB17: 6.05604 | AE17: 0.490204 | AF17: 6.23355 | AI17: 1.34984 | AJ17: 8.68157 | AM17: -1.32087 | AN17: 9.60956 | AQ17: -2.3314 | AR17: 2.55971 | AU17: -2.26841 | AV17: 2.98749 | AY17: 1.83297 | AZ17: 2.5921 | BC17: 15.1752 | BD17: 8.60386 | BG17: -0.210074 | BH17: 5.65402 | BK17: -2.36361 | BL17: 2.15857 | BO17: -2.4208 | BP17: 1.54587 | BS17: 15.8458 | BT17: 9.37967 | BW17: -2.36361 | BX17: 2.15846 | CA17: -2.32124 | CB17: 20.8898 | CE17: -0.135714 | CF17: 1.1799
C18: -2.43927 | D18: 3.82446 | G18: -1.96356 | H18: 6.90824 | K18: -2.19759 | L18: 5.76426 | O18: -1.54662 | P18: 6.84858 | S18: -2.54916 | T18: 1.53517 | W18: 11.0392 | X18: 11.6856 | AA18: -1.49235 | AB18: 5.75349 | AE18: 0.150648 | AF18: 6.29569 | AI18: 1.46551 | AJ18: 8.49308 | AM18: -1.37686 | AN18: 9.71011 | AQ18: -2.24199 | AR18: 3.18855 | AU18: -2.29259 | AV18: 2.72204 | AY18: 1.75451 | AZ18: 4.27156 | BC18: 15.1751 | BD18: 8.60386 | BG18: -0.146501 | BH18: 5.59255 | BK18: -2.42814 | BL18: 1.67727 | BO18: -2.45216 | BP18: 1.32445 | BS18: 15.8455 | BT18: 9.37934 | BW18: -2.42814 | BX18: 1.67716 | CA18: -2.40303 | CB18: 20.0823 | CE18: -0.410377 | CF18: 3.56751
C19: -2.43012 | D19: 4.08543 | G19: -2.04672 | H19: 6.78367 | K19: -2.25693 | L19: 5.15331 | O19: -1.68642 | P19: 6.67095 | S19: -2.5524 | T19: 1.94162 | W19: 11.1299 | X19: 11.7627 | AA19: -1.55331 | AB19: 5.76405 | AE19: -0.0599346 | AF19: 6.01977 | AI19: 1.63762 | AJ19: 8.16424 | AM19: -1.50974 | AN19: 10.2958 | AQ19: -2.13366 | AR19: 3.87129 | AU19: -2.36165 | AV19: 2.23872 | AY19: 1.60798 | AZ19: 6.45668 | BC19: 15.061 | BD19: 8.43193 | BG19: 0.0506106 | BH19: 5.70962 | BK19: -2.44948 | BL19: 1.53367 | BO19: -2.45689 | BP19: 1.29504 | BS19: 15.7383 | BT19: 9.43287 | BW19: -2.44948 | BX19: 1.53356 | CA19: -2.43314 | CB19: 19.8544 | CE19: -0.513775 | CF19: 4.11666
C20: -2.49079 | D20: 2.36577 | G20: -2.12591 | H20: 6.03338 | K20: -2.2928 | L20: 4.81402 | O20: -1.72934 | P20: 6.65971 | S20: -2.52622 | T20: 3.79924 | W20: 13.7535 | X20: 11.5288 | AA20: -1.73324 | AB20: 5.67619 | AE20: -0.110783 | AF20: 6.0843 | AI20: 1.8682 | AJ20: 3.44431 | AM20: -1.60521 | AN20: 10.9976 | AQ20: -2.35482 | AR20: 11.6019 | AU20: -2.43026 | AV20: 1.63205 | AY20: 1.479 | AZ20: 6.26458 | BC20: 15.061 | BD20: 8.43192 | BG20: 0.424251 | BH20: 5.82612 | BK20: -2.45514 | BL20: 1.47793 | BO20: -2.49586 | BP20: 0.994666 | BS20: 15.7381 | BT20: 9.43289 | BW20: -2.45514 | BX20: 1.47782 | CA20: -2.54128 | CB20: 11.8701 | CE20: -0.75818 | CF20: 5.62178
... C43: -0.998433 | D43: 6.8524 | G43: -2.01483 | H43: 6.72126 | K43: -1.85061 | L43: 7.27438 | O43: -2.29662 | P43: 4.82567 | S43: -0.491851 | T43: 8.32298 | W43: 16.0427 | X43: 6.86238 | AA43: -2.25253 | AB43: 8.50999 | AE43: -2.46259 | AF43: 1.68095 | AI43: -2.31722 | AJ43: 9.37875 | AM43: -2.42899 | AN43: 2.58941 | AQ43: -0.205602 | AR43: 5.82471 | AU43: -1.38185 | AV43: 10.8324 | AY43: -2.09169 | AZ43: 4.29012 | BC43: 11.2006 | BD43: 10.7655 | BG43: -2.29299 | BH43: 2.90224 | BK43: -1.72736 | BL43: 13.7219 | BO43: -1.43144 | BP43: 13.6995 | BS43: 15.9937 | BT43: 8.56562 | BW43: -1.72736 | BX43: 13.721 | CA43: 1.70569 | CB43: 2.05707 | CE43: -2.55695 | CF43: 6.90868
C44: -0.892146 | D44: 6.86534 | G44: -1.88589 | H44: 7.03493 | K44: -1.72852 | L44: 7.39198 | O44: -2.2693 | P44: 4.94782 | S44: -0.381463 | T44: 8.31953 | W44: 16.1442 | X44: 6.91493 | AA44: -2.17811 | AB44: 8.21991 | AE44: -2.51978 | AF44: 1.08169 | AI44: -2.35441 | AJ44: 9.42069 | AM44: -2.42392 | AN44: 2.64073 | AQ44: -0.414548 | AR44: 5.99246 | AU44: -1.30786 | AV44: 10.6761 | AY44: -2.15888 | AZ44: 4.04401 | BC44: 11.2824 | BD44: 10.4937 | BG44: -2.32877 | BH44: 2.63075 | BK44: -1.55178 | BL44: 12.3438 | BO44: -1.32602 | BP44: 13.2341 | BS44: 16.0824 | BT44: 8.30883 | BW44: -1.55178 | BX44: 12.3437 | CA44: 1.70185 | CB44: 3.52516
C45: -0.716934 | D45: 6.80235 | G45: -1.77356 | H45: 6.94938 | K45: -1.60012 | L45: 7.22416 | O45: -2.20201 | P45: 5.35856 | S45: -0.146633 | T45: 8.27302 | W45: 15.0546 | X45: 11.8647 | AA45: -2.15854 | AB45: 8.18071 | AE45: -2.52537 | AF45: 1.01828 | AI45: -2.44287 | AJ45: 7.56579 | AM45: -2.38993 | AN45: 3.00717 | AQ45: -0.568965 | AR45: 5.85551 | AU45: -1.14573 | AV45: 10.0498 | AY45: -2.2384 | AZ45: 3.69193 | BC45: 13.4103 | BD45: 10.0857 | BG45: -2.37643 | BH45: 2.32037 | BK45: -1.43092 | BL45: 12.0841 | BO45: -1.198 | BP45: 12.8713 | BS45: 15.1696 | BT45: 8.90053 | BW45: -1.43092 | BX45: 12.0809 | CA45: 1.65234 | CB45: 4.3467 | CE45: 1.15367 | CF45: -1.49862
C46: -0.475352 | D46: 6.81322 | G46: -1.72191 | H46: 6.84456 | K46: -1.49275 | L46: 7.44947 | O46: -2.10864 | P46: 5.97581 | S46: 0.0169083 | T46: 8.50821 | W46: 15.0377 | X46: 11.839 | AA46: -2.1417 | AB46: 8.21637 | AE46: -2.57368 | AF46: 0.819705 | AI46: -2.46316 | AJ46: 7.10442 | AM46: -2.33587 | AN46: 3.57389 | AQ46: -0.787563 | AR46: 5.63413 | AU46: -1.05698 | AV46: 9.92922 | AY46: -2.2759 | AZ46: 3.54552 | BC46: 13.2755 | BD46: 10.3582 | BG46: -2.43957 | BH46: 1.7568 | BK46: -1.32921 | BL46: 11.8866 | BO46: -1.04119 | BP46: 12.3628 | BS46: 15.2569 | BT46: 8.92105 | BW46: -1.32921 | BX46: 11.8825 | CA46: 1.48857 | CB46: 7.61555 | CE46: 1.43377 | CF46: 0.652821
C47: -0.384838 | D47: 7.00497 | G47: -1.67819 | H47: 6.72815 | K47: -1.34781 | L47: 7.46961 | O47: -2.08046 | P47: 6.26643 | S47: 0.231233 | T47: 8.8909 | W47: 15.0546 | X47: 11.8648 | AA47: -2.04564 | AB47: 8.24928 | AE47: -2.56869 | AF47: 1.42852 | AI47: -2.48321 | AJ47: 6.30214 | AM47: -2.3241 | AN47: 3.69739 | AQ47: -0.984053 | AR47: 5.50927 | AU47: -0.83053 | AV47: 9.74227 | AY47: -2.30572 | AZ47: 3.37866 | BC47: 13.4105 | BD47: 10.0856 | BG47: -2.45265 | BH47: 1.66118 | BK47: -1.19677 | BL47: 11.5933 | BO47: -0.906093 | BP47: 11.9974 | BS47: 15.1695 | BT47: 8.9006 | BW47: -1.19677 | BX47: 11.5903 | CA47: 1.40693 | CB47: 7.43187 | CE47: 1.49757 | CF47: 1.30883
C48: -0.136477 | D48: 7.2078 | G48: -1.53929 | H48: 6.44163 | K48: -1.27555 | L48: 7.49751 | O48: -1.96591 | P48: 7.00217 | S48: 0.231233 | T48: 8.8909 | W48: 15.1705 | X48: 11.5108 | AA48: -1.95696 | AB48: 8.6915 | AE48: -2.54266 | AF48: 2.66163 | AI48: -2.54725 | AJ48: 3.32001 | AM48: -2.23424 | AN48: 4.20641 | AQ48: -1.13344 | AR48: 5.41027 | AU48: -0.750894 | AV48: 9.68084 | AY48: -2.36702 | AZ48: 2.99865 | BC48: 13.5587 | BD48: 10.1823 | BG48: -2.49927 | BH48: 1.18279 | BK48: -1.04288 | BL48: 11.1186 | BO48: -0.757246 | BP48: 11.6055 | BS48: 15.0568 | BT48: 9.02665 | BW48: -1.04288 | BX48: 11.1153 | CA48: 1.21356 | CB48: 6.99084 | CE48: 1.6454 | CF48: 1.11302
C49: -0.00840183 | D49: 7.15845 | G49: -1.45198 | H49: 6.49854 | K49: -1.19463 | L49: 7.35382 | O49: -1.91488 | P49: 7.25678 | S49: 0.474704 | T49: 8.67304 | W49: 15.1706 | X49: 11.5107 | AA49: -1.90318 | AB49: 8.5495 | AE49: -2.48127 | AF49: 5.08834 | AI49: -2.57112 | AJ49: 1.79438 | AM49: -2.12431 | AN49: 4.63303 | AQ49: -1.35667 | AR49: 5.27615 | AU49: -0.750894 | AV49: 9.68084 | AY49: -2.4312 | AZ49: 2.61333 | BC49: 13.5589 | BD49: 10.183 | BG49: -2.54897 | BH49: 0.691627 | BK49: -0.89859 | BL49: 10.7695 | BO49: -0.42229 | BP49: 10.9187 | BS49: 15.0568 | BT49: 9.02665 | BW49: -0.89859 | BX49: 10.7661 | CA49: 1.06437 | CB49: 6.87804 | CE49: 1.68556 | CF49: 1.12684
C50: 0.181318 | D50: 7.30882 | G50: -1.34555 | H50: 6.65669 | K50: -1.03665 | L50: 7.23422 | O50: -1.7328 | P50: 7.41637 | S50: 0.614332 | T50: 8.68076 | W50: 15.2908 | X50: 11.1938 | AA50: -1.7869 | AB50: 8.45129 | AE50: -2.46119 | AF50: 5.69313 | AI50: -2.57411 | AJ50: 0.769447 | AM50: -2.11299 | AN50: 4.7189 | AQ50: -1.54012 | AR50: 5.14849 | AU50: -0.432194 | AV50: 9.40112 | AY50: -2.44542 | AZ50: 2.54528 | BC50: 13.7068 | BD50: 10.5872 | BG50: -2.5537 | BH50: 0.701972 | BK50: -0.756436 | BL50: 10.5625 | BO50: -0.36184 | BP50: 10.7879 | BS50: 14.9969 | BT50: 8.93341 | BW50: -0.756436 | BX50: 10.561 | CA50: 0.77522 | CB50: 6.3019 | CE50: 1.68127 | CF50: 3.58373
C51: 0.47321 | D51: 7.25665 | G51: -1.18843 | H51: 6.8379 | K51: -0.936387 | L51: 7.33383 | O51: -1.68785 | P51: 7.44379 | S51: 0.836981 | T51: 9.07563 | W51: 15.2908 | X51: 11.1938 | AA51: -1.70363 | AB51: 8.52799 | AE51: -2.44072 | AF51: 6.18382 | AI51: -2.55807 | AJ51: 0.541664 | AM51: -2.09945 | AN51: 4.72797 | AQ51: -1.6223 | AR51: 5.01584 | AU51: -0.350441 | AV51: 9.37961 | AY51: -2.49438 | AZ51: 1.82076 | BC51: 13.707 | BD51: 10.5872 | BG51: -2.58848 | BH51: 1.938 | BK51: -0.480711 | BL51: 9.98176 | BO51: -0.284196 | BP51: 10.58 | BS51: 11.2858 | BT51: 10.8313 | BW51: -0.480711 | BX51: 9.97999 | CA51: 0.745434 | CB51: 6.30993 | CE51: 1.68099 | CF51: 3.7028
C52: 0.511904 | D52: 7.31646 | G52: -1.01336 | H52: 7.50245 | K52: -0.725118 | L52: 7.6476 | O52: -1.50162 | P52: 6.90439 | S52: 1.02801 | T52: 8.81828 | W52: 15.3109 | X52: 11.1766 | AA52: -1.67714 | AB52: 8.51853 | AE52: -2.35313 | AF52: 7.99176 | AI52: -2.51353 | AJ52: 0.871554 | AM52: -1.98019 | AN52: 4.77191 | AQ52: -1.78861 | AR52: 5.01703 | AU52: -0.330367 | AV52: 9.36297 | AY52: -2.53537 | AZ52: 1.22235 | BC52: 13.8514 | BD52: 10.6655 | BG52: -2.58413 | BH52: 3.9482 | BK52: -0.473546 | BL52: 9.97516 | BO52: 0.0105835 | BP52: 9.97847 | BS52: 11.2034 | BT52: 10.5861 | BW52: -0.473546 | BX52: 9.9734 | CA52: 0.680009 | CB52: 6.36655 | CE52: 1.4673 | CF52: 7.69909
C53: 0.550819 | D53: 7.30181 | G53: -0.895669 | H53: 7.44011 | K53: -0.488643 | L53: 7.63322 | O53: -1.45174 | P53: 6.96048 | S53: 1.14768 | T53: 8.70492 | W53: 15.6283 | X53: 11.4256 | AA53: -1.62469 | AB53: 8.28097 | AE53: -2.30966 | AF53: 8.40247 | AI53: -2.50526 | AJ53: 0.925254 | AM53: -1.88451 | AN53: 5.00218 | AQ53: -1.89628 | AR53: 4.80959 | AU53: -0.293205 | AV53: 9.32174 | AY53: -2.53923 | AZ53: 1.19309 | BC53: 13.8515 | BD53: 10.6655 | BG53: -2.5462 | BH53: 7.8735 | BK53: -0.230422 | BL53: 9.95748 | BO53: 0.332138 | BP53: 9.31754 | BS53: 11.2033 | BT53: 10.5861 | BW53: -0.230422 | BX53: 9.95699 | CA53: 0.680009 | CB53: 6.36655 | CE53: 1.43685 | CF53: 8.23398
C54: 0.873998 | D54: 7.63077 | G54: -0.721136 | H54: 7.33906 | K54: -0.391551 | L54: 7.6969 | O54: -1.31282 | P54: 7.11911 | S54: 1.40096 | T54: 8.03726 | W54: 15.5548 | X54: 11.5217 | AA54: -1.44375 | AB54: 7.87602 | AE54: -2.22811 | AF54: 8.9667 | AI54: -2.46374 | AJ54: 1.34299 | AM54: -1.77815 | AN54: 5.07982 | AQ54: -1.98966 | AR54: 4.45888 | AU54: 0.09652 | AV54: 9.0818 | AY54: -2.58792 | AZ54: 0.942588 | BC54: 13.8515 | BD54: 10.6655 | BG54: -2.52374 | BH54: 10.2217 | BK54: 0.0709532 | BL54: 9.4313 | BO54: 0.392703 | BP54: 9.20119 | BS54: 11.2032 | BT54: 10.5861 | BW54: 0.0709532 | BX54: 9.43004 | CA54: 0.441231 | CB54: 6.67529 | CE54: 1.3736 | CF54: 8.01207
C55: 1.34611 | D55: 6.44185 | G55: -0.479028 | H55: 6.78935 | K55: -0.151522 | L55: 8.10271 | O55: -1.03859 | P55: 7.40456 | S55: 1.42358 | T55: 8.01521 | W55: 15.6285 | X55: 11.4253 | AA55: -1.28254 | AB55: 7.84476 | AE55: -2.18191 | AF55: 9.11957 | AI55: -2.42203 | AJ55: 1.77225 | AM55: -1.60835 | AN55: 5.1073 | AQ55: -2.10731 | AR55: 4.02641 | AU55: 0.367735 | AV55: 9.01875 | AY55: -2.5883 | AZ55: 1.91571 | BC55: 13.8817 | BD55: 10.7578 | BG55: -2.50179 | BH55: 12.0356 | BK55: 0.0909562 | BL55: 9.41415 | BO55: 1.76463 | BP55: 1.8 | BS55: 11.0538 | BT55: 10.3051 | BW55: 0.0909562 | BX55: 9.4129 | CA55: 0.314333 | CB55: 6.62959 | CE55: 1.10134 | CF55: 6.93427
C56: 1.36443 | D56: 6.46446 | G56: -0.388917 | H56: 6.60303 | K56: -0.00757466 | L56: 8.30542 | O56: -0.899688 | P56: 7.60404 | S56: 1.43851 | T56: 8.00086 | W56: 15.7395 | X56: 11.1846 | AA56: -1.26091 | AB56: 7.85777 | AE56: -2.12916 | AF56: 9.27204 | AI56: -2.41715 | AJ56: 1.83676 | AM56: -1.52887 | AN56: 5.13318 | AQ56: -2.12179 | AR56: 3.95777 | AU56: 0.477279 | AV56: 8.9581 | AY56: -2.58213 | AZ56: 3.66647 | BC56: 16.898 | BD56: 10.6355 | BG56: -2.43155 | BH56: 14.5934 | BK56: 0.107888 | BL56: 9.38445 | BO56: 1.76266 | BP56: 2.38523 | BS56: 11.0537 | BT56: 10.3052 | BW56: 0.107888 | BX56: 9.38318 | CA56: -0.0213941 | CB56: 6.44759 | CE56: 0.942814 | CF56: 6.72729
... C85: -1.97262 | D85: 8.54356 | G85: 0.234662 | H85: 6.79774 | K85: -0.110283 | L85: 7.27603 | O85: 1.03571 | P85: 7.86136 | S85: 0.989052 | T85: 6.72903 | W85: 17.1208 | X85: 3.41233 | AA85: 1.41048 | AB85: 6.25115 | AE85: 1.50562 | AF85: 8.01332 | AI85: 1.38798 | AJ85: 7.10601 | AM85: 1.48477 | AN85: 6.26559 | AQ85: 0.386599 | AR85: 9.15903 | AU85: -0.997123 | AV85: 5.8055 | AY85: 0.0801987 | AZ85: 9.06122 | BC85: 15.1941 | BD85: 10.1346 | BG85: 0.821351 | BH85: 8.77887 | BK85: 0.613293 | BL85: 5.80595 | BO85: 1.44443 | BP85: 6.16907 | BS85: 17.0865 | BT85: 3.54344 | BW85: 0.613293 | BX85: 5.80598 | CA85: -0.407005 | CB85: 8.32662 | CE85: -2.45639 | CF85: 1.15092
C86: -2.05001 | D86: 8.20366 | G86: 0.045106 | H86: 6.70076 | K86: -0.0387775 | L86: 7.24404 | O86: 0.844017 | P86: 8.00689 | S86: 1.31017 | T86: 6.81592 | AA86: 1.29824 | AB86: 6.20552 | AE86: 1.66038 | AF86: 7.59041 | AI86: 1.42301 | AJ86: 7.15029 | AM86: 1.25238 | AN86: 6.08933 | AQ86: 0.437481 | AR86: 9.21851 | AU86: -1.14563 | AV86: 5.63759 | AY86: 0.262373 | AZ86: 8.93993 | BC86: 15.1541 | BD86: 10.1191 | BG86: 0.862387 | BH86: 8.6926 | BK86: 0.826011 | BL86: 5.77421 | BO86: 1.4291 | BP86: 6.24824 | BS86: 17.0393 | BT86: 5.19848 | BW86: 0.826011 | BX86: 5.77424 | CA86: -0.510943 | CB86: 8.47593 | CE86: -2.49553 | CF86: 0.764878
C87: -2.12578 | D87: 7.54505 | G87: -0.0243201 | H87: 6.79545 | K87: 0.0338135 | L87: 7.1905 | O87: 0.619529 | P87: 7.73886 | S87: 1.38644 | T87: 6.80882 | AA87: 0.971489 | AB87: 5.89016 | AE87: 1.74307 | AF87: 7.43104 | AI87: 1.65142 | AJ87: 7.2061 | AM87: 1.01808 | AN87: 5.87063 | AQ87: 0.464936 | AR87: 9.25555 | AY87: 0.556504 | AZ87: 8.51825 | BG87: 1.17365 | BH87: 8.17581 | BK87: 1.01407 | BL87: 5.95395 | BO87: 1.17197 | BP87: 7.24731 | BW87: 1.01407 | BX87: 5.954 | CA87: -0.0380646 | CB87: 7.38147 | CE87: -2.52597 | CF87: 0.468484
C88: -2.21382 | D88: 6.86619 | G88: -0.0952967 | H88: 6.78024 | K88: 0.220814 | L88: 7.26425 | O88: 0.481098 | P88: 7.81028 | S88: 1.64012 | T88: 7.1138 | AA88: 0.951594 | AB88: 5.87951 | AE88: 1.76613 | AF88: 6.82515 | AI88: 1.85298 | AJ88: 3.67914 | AQ88: 0.684572 | AR88: 9.22937 | AY88: 0.578329 | AZ88: 8.50456 | BG88: 1.23782 | BH88: 7.98174 | BK88: 1.15693 | BL88: 5.99711 | BO88: 1.13556 | BP88: 7.37513 | BW88: 1.15693 | BX88: 5.99715 | CA88: 0.243666 | CB88: 6.83543 | CE88: -2.5312 | CF88: 0.569897
C89: -2.25585 | D89: 6.45072 | G89: -0.284532 | H89: 7.0214 | K89: 0.564885 | L89: 7.06227 | O89: 0.235894 | P89: 7.99539 | S89: 1.70999 | T89: 7.19795 | AA89: 0.909385 | AB89: 5.89494 | AE89: 1.91057 | AF89: 2.41905 | AI89: 1.89573 | AJ89: 2.8386 | AQ89: 0.882077 | AR89: 9.23859 | AY89: 0.593136 | AZ89: 8.47518 | BK89: 1.33014 | BL89: 6.23411 | BO89: 0.823065 | BP89: 8.15075 | BW89: 1.33014 | BX89: 6.23417 | CA89: 0.338306 | CB89: 6.64776 | CE89: -2.56431 | CF89: 1.01782
C90: -2.3231 | D90: 5.18806 | K90: 0.681728 | L90: 6.96282 | S90: 1.73789 | T90: 6.77618 | AA90: 0.909385 | AB90: 5.89494 | AE90: 1.91055 | AF90: 2.40617 | AI90: 1.89655 | AJ90: 2.81491 | AQ90: 0.911836 | AR90: 9.22358 | BK90: 1.42712 | BL90: 6.33751 | BO90: 0.80614 | BP90: 8.19431 | BW90: 1.42712 | BX90: 6.33758 | CA90: 0.479891 | CB90: 6.61484 | CE90: -2.57117 | CF90: 2.9597
C91: -2.34004 | D91: 4.95328 | K91: 0.797655 | L91: 6.66014 | AA91: 0.629795 | AB91: 6.12576 | AE91: 1.90999 | AF91: 2.74693 | AI91: 1.89662 | AJ91: 2.82132 | AQ91: 1.27539 | AR91: 8.69289 | BK91: 1.48925 | BL91: 6.52995 | BO91: 0.680056 | BP91: 8.48821 | BW91: 1.48925 | BX91: 6.52994 | CA91: 0.617545 | CB91: 6.53496 | CE91: -2.55695 | CF91: 6.90868
...

Sheet Cp(y=5m)
A2: Sección del motor
C3: X | D3: Y | G3: X | H3: Y | K3: X | L3: Y | O3: X | P3: Y | S3: X | T3: Y | W3: X | X3: Y | AA3: X | AB3: Y | AE3: X | AF3: Y | AI3: X | AJ3: Y | AM3: X | AN3: Y | AQ3: X | AR3: Y | AU3: X | AV3: Y | AY3: X | AZ3: Y | BC3: X | BD3: Y | BG3: X | BH3: Y | BK3: X | BL3: Y | BO3: X | BP3: Y | BS3: X | BT3: Y | BW3: X | BX3: Y | CA3: X | CB3: Y | CE3: X | CF3: Y
